#VRML_SIM R2021a utf8
# tags: static

PROTO gripper[
    field SFVec3f                               translation     0.16 0.05 0
    field SFRotation                            rotation        0 1 0 0
    field MFNode                                left_motor    []
    field MFNode                                right_motor   []
    field SFNode                                appearance     NULL
    field SFString                              name            "gripper"
]

{
    DEF gripper Solid {
        translation IS translation
        rotation IS rotation
        children [
            Transform{
                translation 0 0.01 -0.05
                children[
                    DEF Top_Plate Transform {
                        translation -0.03 -0.009 0.05
                        children [
                            Shape {
                                appearance IS appearance
                                geometry Mesh {
                                    url [
                                    "meshes/Machine_Tool/Bottom_Plate.stl"
                                    ]
                                }
                            }
                        ]
                    }
                    DEF Bottom_Plate Solid {
                        translation 0.03 -0.017 0.05
                        rotation 0 0 1 3.14159
                        children [
                            Shape {
                                appearance IS appearance
                                geometry Mesh {
                                    url [
                                    "meshes/Machine_Tool/Top_Plate.stl"
                                    ]
                                }
                            }
                        ]
                        name "solid(1)"
                        boundingObject Transform {
                            translation 0.0301 0.007 0.019
                            children [
                                Cylinder {
                                    height 0.013
                                    radius 0.031
                                }
                            ]
                        }
                        physics Physics {
                            density -1
                            mass 0.02
                        }
                    }
                    DEF Servo_gear HingeJoint {
                        jointParameters HingeJointParameters {
                            axis 0 -1 0
                            anchor 0.014 -0.01 0.0739
                        }
                        device IS left_motor
                        endPoint Solid {
                            translation 0.014 -0.01 0.0739
                            rotation -0.9999999999999999 0 0 1.5707953071795862
                            children [
                                Shape {
                                    appearance IS appearance
                                    geometry Mesh {
                                        url [
                                            "meshes/Machine_Tool/Servo_Gear.stl"
                                        ]
                                    }
                                }
                                DEF Left_Gripper HingeJoint {
                                    jointParameters HingeJointParameters {
                                        axis 0 0 1
                                        anchor 0.04 0 -0.002
                                    }
                                    endPoint DEF left_gripper Solid {
                                        translation 0.04 0 -0.002
                                        rotation 0 0 -0.9999999999999999 1.5707953071795862
                                        children [
                                            Shape {
                                                appearance IS appearance
                                                geometry Mesh {
                                                    url [
                                                    "meshes/Machine_Tool/Gripper_Left.stl"
                                                    ]
                                                }
                                            }
                                        ]
                                        name "left_gripper"
                                        boundingObject Transform {
                                            translation 0.03 -0.005 -0.001
                                            children [
                                                Box {
                                                    size 0.07 0.017 0.017
                                                }
                                            ]
                                        }
                                        physics Physics {
                                            density -1
                                            mass 0.03
                                        }
                                    }
                                }
                            ]
                            name "solid(2)"
                            boundingObject Transform {
                            translation 0.016 0 -0.0031
                            children [
                                Box {
                                    size 0.051 0.005 0.0056
                                }
                            ]
                            }
                            physics Physics {
                                density -1
                                mass 0.01
                                centerOfMass [
                                    0.01 0 0
                                ]
                            }
                        }
                    }
                    DEF Pivot_Servo HingeJoint {
                        jointParameters HingeJointParameters {
                            axis 0 1 0
                            anchor 0.007 -0.01 0.0939
                        }
                        endPoint Solid {
                            translation 0.007 -0.01 0.0939
                            rotation -0.9999999999999999 0 0 1.5707953071795862
                            children [
                                Shape {
                                    appearance IS appearance
                                    geometry Mesh {
                                        url [
                                            "meshes/Machine_Tool/Pivot_Arm.stl"
                                        ]
                                    }
                                }
                                HingeJoint {
                                    jointParameters HingeJointParameters {
                                        axis 0 0 1
                                        anchor 0.04 0 0
                                    }
                                    endPoint SolidReference {
                                        solidName "left_gripper"
                                    }
                                }
                            ]
                            name "solid(3)"
                            boundingObject Transform {
                            translation 0.02 0 -0.003
                            children [
                                Box {
                                    size 0.044 0.005 0.0056
                                }
                            ]
                            }
                            physics Physics {
                                density -1
                                mass 0.01
                                centerOfMass [
                                    0.01 0 0
                                ]
                            }
                        }
                    }
                    DEF Idle_gear HingeJoint {
                        jointParameters HingeJointParameters {
                            axis 0 1 0
                            anchor -0.014 -0.01 0.0739
                        }
                        device IS right_motor
                        endPoint Solid {
                            translation -0.014 -0.01 0.0739
                            rotation -0.9999999999999999 0 0 1.5707953071795862
                            children [
                                Shape {
                                    appearance IS appearance
                                    geometry Mesh {
                                        url [
                                            "meshes/Machine_Tool/Idle_Gear.stl"
                                        ]
                                    }
                                }
                                DEF Right_Gripper HingeJoint {
                                    jointParameters HingeJointParameters {
                                        axis 0 0 1
                                        anchor -0.04 0 -0.004
                                    }
                                    endPoint DEF right_gripper Solid {
                                        translation -0.04 0 -0.004
                                        rotation 0 0 1 1.5708
                                        children [
                                            Shape {
                                                appearance IS appearance
                                                geometry Mesh {
                                                    url [
                                                        "meshes/Machine_Tool/Gripper_Right.stl"
                                                    ]
                                                }
                                            }
                                        ]
                                        name "right_gripper"
                                        boundingObject Transform {
                                            translation -0.03 -0.005 0.001
                                            children [
                                                Box {
                                                    size 0.07 0.017 0.017
                                                }
                                            ]
                                        }
                                        physics Physics {
                                            density -1
                                            mass 0.03
                                        }
                                    }
                                }
                            ]
                            name "solid(4)"
                            boundingObject Transform {
                                translation -0.016 0 -0.0031
                                children [
                                    Box {
                                        size 0.051 0.005 0.0056
                                    }
                                ]
                            }
                            physics Physics {
                                density -1
                                mass 0.01
                                centerOfMass [
                                    0.01 0 0
                                ]
                            }
                        }
                    }
                    DEF Pivot_Idle HingeJoint {
                        jointParameters HingeJointParameters {
                            axis 0 1 0
                            anchor -0.007 -0.01 0.0939
                        }
                        endPoint Solid {
                            translation -0.007 -0.01 0.0939
                            rotation -3.3905013482585576e-09 0.7071062811861719 0.7071072811865696 3.14159
                            children [
                                Shape {
                                    appearance IS appearance
                                    geometry Mesh {
                                        url [
                                            "meshes/Machine_Tool/Pivot_Arm.stl"
                                        ]
                                    }
                                }
                                HingeJoint {
                                    jointParameters HingeJointParameters {
                                        axis 0 0 1
                                        anchor 0.04 0 0
                                    }
                                    endPoint SolidReference {
                                        solidName "right_gripper"
                                    }
                                }
                            ]
                            name "solid(5)"
                            boundingObject Transform {
                                translation 0.02 0 -0.003
                                children [
                                    Box {
                                        size 0.044 0.005 0.0056
                                    }
                                ]
                            }
                            physics Physics {
                                density -1
                                mass 0.01
                                centerOfMass [
                                    0.01 0 0
                                ]
                            }
                        }
                    }
                ]
            }
        ]
        boundingObject Transform {
            translation 0 0.008 0.02
                children [
                    Cylinder {
                        height 0.013
                        radius 0.031
                    }
                ]
        }
        physics Physics {
            density -1
            mass 0.03
        }
        name IS name
        }
}
